Workbook

Sheet Daily_Analysis
E2: Rule: Labeled 'High-Value Merchant Day' if daily total > ₹5,000 and Region is not East.
A3: Merchant Name | B3: Date | C3: Region | D3: Total Amount | E3: Value Classification
A4: Merchant_001 | B4: 46027 | C4: South | D4: 1499 | E4: =IF(AND(D4 > 5000, C4 <> "East"), "High-Value Merchant Day", "Standard") -> Standard
B5: 46028 | C5: South | D5: 149 | E5: =IF(AND(D5 > 5000, C5 <> "East"), "High-Value Merchant Day", "Standard") -> Standard
B6: 46031 | C6: South | D6: 5048 | E6: =IF(AND(D6 > 5000, C6 <> "East"), "High-Value Merchant Day", "Standard") -> High-Value Merchant Day
B7: 46033 | C7: South | D7: 299 | E7: =IF(AND(D7 > 5000, C7 <> "East"), "High-Value Merchant Day", "Standard") -> Standard
B8: 46034 | C8: South | D8: 149 | E8: =IF(AND(D8 > 5000, C8 <> "East"), "High-Value Merchant Day", "Standard") -> Standard
B9: 46039 | C9: South | D9: 149 | E9: =IF(AND(D9 > 5000, C9 <> "East"), "High-Value Merchant Day", "Standard") -> Standard
B10: 46045 | C10: South | D10: 3148 | E10: =IF(AND(D10 > 5000, C10 <> "East"), "High-Value Merchant Day", "Standard") -> Standard
A11: Merchant_002 | B11: 46029 | C11: West | D11: 499 | E11: =IF(AND(D11 > 5000, C11 <> "East"), "High-Value Merchant Day", "Standard") -> Standard
B12: 46030 | C12: West | D12: 299 | E12: =IF(AND(D12 > 5000, C12 <> "East"), "High-Value Merchant Day", "Standard") -> Standard
B13: 46034 | C13: West | D13: 348 | E13: =IF(AND(D13 > 5000, C13 <> "East"), "High-Value Merchant Day", "Standard") -> Standard
B14: 46035 | C14: West | D14: 49 | E14: =IF(AND(D14 > 5000, C14 <> "East"), "High-Value Merchant Day", "Standard") -> Standard
B15: 46037 | C15: West | D15: 1499 | E15: =IF(AND(D15 > 5000, C15 <> "East"), "High-Value Merchant Day", "Standard") -> Standard
B16: 46041 | C16: West | D16: 49 | E16: =IF(AND(D16 > 5000, C16 <> "East"), "High-Value Merchant Day", "Standard") -> Standard
B17: 46044 | C17: West | D17: 299 | E17: =IF(AND(D17 > 5000, C17 <> "East"), "High-Value Merchant Day", "Standard") -> Standard
B18: 46048 | C18: West | D18: 299 | E18: =IF(AND(D18 > 5000, C18 <> "East"), "High-Value Merchant Day", "Standard") -> Standard
B19: 46052 | C19: West | D19: 299 | E19: =IF(AND(D19 > 5000, C19 <> "East"), "High-Value Merchant Day", "Standard") -> Standard
A20: Merchant_003 | B20: 46025 | C20: East | D20: 198 | E20: =IF(AND(D20 > 5000, C20 <> "East"), "High-Value Merchant Day", "Standard") -> Standard
B21: 46027 | C21: East | D21: 99 | E21: =IF(AND(D21 > 5000, C21 <> "East"), "High-Value Merchant Day", "Standard") -> Standard
B22: 46028 | C22: East | D22: 898 | E22: =IF(AND(D22 > 5000, C22 <> "East"), "High-Value Merchant Day", "Standard") -> Standard
B23: 46029 | C23: East | D23: 798 | E23: =IF(AND(D23 > 5000, C23 <> "East"), "High-Value Merchant Day", "Standard") -> Standard
B24: 46030 | C24: East | D24: 149 | E24: =IF(AND(D24 > 5000, C24 <> "East"), "High-Value Merchant Day", "Standard") -> Standard
B25: 46035 | C25: East | D25: 198 | E25: =IF(AND(D25 > 5000, C25 <> "East"), "High-Value Merchant Day", "Standard") -> Standard
B26: 46038 | C26: East | D26: 4999 | E26: =IF(AND(D26 > 5000, C26 <> "East"), "High-Value Merchant Day", "Standard") -> Standard
B27: 46042 | C27: East | D27: 99 | E27: =IF(AND(D27 > 5000, C27 <> "East"), "High-Value Merchant Day", "Standard") -> Standard
B28: 46044 | C28: East | D28: 499 | E28: =IF(AND(D28 > 5000, C28 <> "East"), "High-Value Merchant Day", "Standard") -> Standard
B29: 46045 | C29: East | D29: 49 | E29: =IF(AND(D29 > 5000, C29 <> "East"), "High-Value Merchant Day", "Standard") -> Standard
B30: 46048 | C30: East | D30: 149 | E30: =IF(AND(D30 > 5000, C30 <> "East"), "High-Value Merchant Day", "Standard") -> Standard
B31: 46051 | C31: East | D31: 49 | E31: =IF(AND(D31 > 5000, C31 <> "East"), "High-Value Merchant Day", "Standard") -> Standard
B32: 46052 | C32: East | D32: 49 | E32: =IF(AND(D32 > 5000, C32 <> "East"), "High-Value Merchant Day", "Standard") -> Standard
A33: Merchant_004 | B33: 46024 | C33: East | D33: 149 | E33: =IF(AND(D33 > 5000, C33 <> "East"), "High-Value Merchant Day", "Standard") -> Standard
B34: 46034 | C34: East | D34: 49 | E34: =IF(AND(D34 > 5000, C34 <> "East"), "High-Value Merchant Day", "Standard") -> Standard
B35: 46035 | C35: East | D35: 948 | E35: =IF(AND(D35 > 5000, C35 <> "East"), "High-Value Merchant Day", "Standard") -> Standard
B36: 46038 | C36: East | D36: 799 | E36: =IF(AND(D36 > 5000, C36 <> "East"), "High-Value Merchant Day", "Standard") -> Standard
B37: 46039 | C37: East | D37: 1499 | E37: =IF(AND(D37 > 5000, C37 <> "East"), "High-Value Merchant Day", "Standard") -> Standard
B38: 46046 | C38: East | D38: 1499 | E38: =IF(AND(D38 > 5000, C38 <> "East"), "High-Value Merchant Day", "Standard") -> Standard
B39: 46047 | C39: East | D39: 1998 | E39: =IF(AND(D39 > 5000, C39 <> "East"), "High-Value Merchant Day", "Standard") -> Standard
A40: Merchant_005 | B40: 46023 | C40: South | D40: 499 | E40: =IF(AND(D40 > 5000, C40 <> "East"), "High-Value Merchant Day", "Standard") -> Standard
B41: 46025 | C41: South | D41: 499 | E41: =IF(AND(D41 > 5000, C41 <> "East"), "High-Value Merchant Day", "Standard") -> Standard
...

Sheet Status_Summary
A2: Merchants | B2: Total Volume | C2: Total Transactions | D2: Unique Transacting Days
A3: Merchant_001 | B3: 10441 | C3: 9 | D3: 7
A4: captured | B4: 10142 | C4: 8 | D4: 6
A5: failed | B5: 299 | C5: 1 | D5: 1
A6: Merchant_002 | B6: 3640 | C6: 10 | D6: 9
A7: captured | B7: 3640 | C7: 10 | D7: 9
A8: Merchant_003 | B8: 8233 | C8: 17 | D8: 13
A9: captured | B9: 8084 | C9: 16 | D9: 13
A10: chargeback | B10: 149 | C10: 1 | D10: 0
A11: Merchant_004 | B11: 6941 | C11: 9 | D11: 7
A12: captured | B12: 6941 | C12: 9 | D12: 7
A13: Merchant_005 | B13: 5839 | C13: 11 | D13: 9
A14: captured | B14: 5340 | C14: 10 | D14: 8
... A27: Grand Total | B27: 65898 | C27: 102 | D27: 81

Sheet ledger
A1: transaction_id | B1: user_id | C1: merchant_id | D1: merchant_name | E1: Region | F1: Category | G1: transaction_time | H1: Short_date | I1: amount_inr | J1: payment_method | K1: status | L1: risk_score | M1: Unique_Day_Flag | N1: MDR_Fee
A2: TXN100000 | B2: 350 | C2: 16 | D2: =IFERROR(VLOOKUP($C2,merchants!$A$2:$D$41,2,FALSE),"Merchant not found") -> Merchant_016 | E2: =IFERROR(VLOOKUP($C2, merchants!$A$2:$D$41, 4, FALSE), "Merchant not found") -> West | F2: =IFERROR(VLOOKUP($C2, merchants!$A$2:$D$41, 3, FALSE), "Merchant not found") -> bill_payment | G2: 46051.467 | H2: =INT(G2) -> 46051 | I2: 2999 | J2: Wallet | K2: captured | L2: 85 | M2: =IF(COUNTIFS($D$2:$D2, $D2, $H$2:$H2, $H2)=1, 1, 0) -> 1 | N2: =_xlfn.IFNA(HLOOKUP($J2, fee_reference!$B$1:$E$2, 2, FALSE), 0) -> 0.015
A3: TXN100001 | B3: 287 | C3: 27 | D3: =IFERROR(VLOOKUP($C3,merchants!$A$2:$D$41,2,FALSE),"Merchant not found") -> Merchant_027 | E3: =IFERROR(VLOOKUP($C3, merchants!$A$2:$D$41, 4, FALSE), "Merchant not found") -> North | F3: =IFERROR(VLOOKUP($C3, merchants!$A$2:$D$41, 3, FALSE), "Merchant not found") -> ecommerce | G3: 46026.492 | H3: =INT(G3) -> 46026 | I3: 49 | J3: UPI | K3: captured | L3: 79 | M3: =IF(COUNTIFS($D$2:$D3, $D3, $H$2:$H3, $H3)=1, 1, 0) -> 1 | N3: =_xlfn.IFNA(HLOOKUP($J3, fee_reference!$B$1:$E$2, 2, FALSE), 0) -> 0
A4: TXN100002 | B4: 122 | C4: 11 | D4: =IFERROR(VLOOKUP($C4,merchants!$A$2:$D$41,2,FALSE),"Merchant not found") -> Merchant_011 | E4: =IFERROR(VLOOKUP($C4, merchants!$A$2:$D$41, 4, FALSE), "Merchant not found") -> North | F4: =IFERROR(VLOOKUP($C4, merchants!$A$2:$D$41, 3, FALSE), "Merchant not found") -> ecommerce | G4: 46046.208 | H4: =INT(G4) -> 46046 | I4: 1499 | J4: Wallet | K4: captured | L4: 22 | M4: =IF(COUNTIFS($D$2:$D4, $D4, $H$2:$H4, $H4)=1, 1, 0) -> 1 | N4: =_xlfn.IFNA(HLOOKUP($J4, fee_reference!$B$1:$E$2, 2, FALSE), 0) -> 0.015
A5: TXN100003 | B5: 92 | C5: 22 | D5: =IFERROR(VLOOKUP($C5,merchants!$A$2:$D$41,2,FALSE),"Merchant not found") -> Merchant_022 | E5: =IFERROR(VLOOKUP($C5, merchants!$A$2:$D$41, 4, FALSE), "Merchant not found") -> South | F5: =IFERROR(VLOOKUP($C5, merchants!$A$2:$D$41, 3, FALSE), "Merchant not found") -> travel | G5: 46051.542 | H5: =INT(G5) -> 46051 | I5: 49 | J5: Netbanking | K5: captured | L5: 100 | M5: =IF(COUNTIFS($D$2:$D5, $D5, $H$2:$H5, $H5)=1, 1, 0) -> 1 | N5: =_xlfn.IFNA(HLOOKUP($J5, fee_reference!$B$1:$E$2, 2, FALSE), 0) -> 0.01
A6: TXN100004 | B6: 343 | C6: 16 | D6: =IFERROR(VLOOKUP($C6,merchants!$A$2:$D$41,2,FALSE),"Merchant not found") -> Merchant_016 | E6: =IFERROR(VLOOKUP($C6, merchants!$A$2:$D$41, 4, FALSE), "Merchant not found") -> West | F6: =IFERROR(VLOOKUP($C6, merchants!$A$2:$D$41, 3, FALSE), "Merchant not found") -> bill_payment | G6: 46052.577 | H6: =INT(G6) -> 46052 | I6: 99 | J6: UPI | K6: captured | L6: 34 | M6: =IF(COUNTIFS($D$2:$D6, $D6, $H$2:$H6, $H6)=1, 1, 0) -> 1 | N6: =_xlfn.IFNA(HLOOKUP($J6, fee_reference!$B$1:$E$2, 2, FALSE), 0) -> 0
A7: TXN100005 | B7: 196 | C7: 3 | D7: =IFERROR(VLOOKUP($C7,merchants!$A$2:$D$41,2,FALSE),"Merchant not found") -> Merchant_003 | E7: =IFERROR(VLOOKUP($C7, merchants!$A$2:$D$41, 4, FALSE), "Merchant not found") -> East | F7: =IFERROR(VLOOKUP($C7, merchants!$A$2:$D$41, 3, FALSE), "Merchant not found") -> grocery | G7: 46028.921 | H7: =INT(G7) -> 46028 | I7: 99 | J7: UPI | K7: captured | L7: 60 | M7: =IF(COUNTIFS($D$2:$D7, $D7, $H$2:$H7, $H7)=1, 1, 0) -> 1 | N7: =_xlfn.IFNA(HLOOKUP($J7, fee_reference!$B$1:$E$2, 2, FALSE), 0) -> 0
A8: TXN100006 | B8: 236 | C8: 23 | D8: =IFERROR(VLOOKUP($C8,merchants!$A$2:$D$41,2,FALSE),"Merchant not found") -> Merchant_023 | E8: =IFERROR(VLOOKUP($C8, merchants!$A$2:$D$41, 4, FALSE), "Merchant not found") -> North | F8: =IFERROR(VLOOKUP($C8, merchants!$A$2:$D$41, 3, FALSE), "Merchant not found") -> travel | G8: 46030.286 | H8: =INT(G8) -> 46030 | I8: 99 | J8: Wallet | K8: captured | L8: 39 | M8: =IF(COUNTIFS($D$2:$D8, $D8, $H$2:$H8, $H8)=1, 1, 0) -> 1 | N8: =_xlfn.IFNA(HLOOKUP($J8, fee_reference!$B$1:$E$2, 2, FALSE), 0) -> 0.015
A9: TXN100007 | B9: 13 | C9: 13 | D9: =IFERROR(VLOOKUP($C9,merchants!$A$2:$D$41,2,FALSE),"Merchant not found") -> Merchant_013 | E9: =IFERROR(VLOOKUP($C9, merchants!$A$2:$D$41, 4, FALSE), "Merchant not found") -> East | F9: =IFERROR(VLOOKUP($C9, merchants!$A$2:$D$41, 3, FALSE), "Merchant not found") -> travel | G9: 46049.301 | H9: =INT(G9) -> 46049 | I9: 99 | J9: UPI | K9: captured | L9: 51 | M9: =IF(COUNTIFS($D$2:$D9, $D9, $H$2:$H9, $H9)=1, 1, 0) -> 1 | N9: =_xlfn.IFNA(HLOOKUP($J9, fee_reference!$B$1:$E$2, 2, FALSE), 0) -> 0
A10: TXN100008 | B10: 36 | C10: 18 | D10: =IFERROR(VLOOKUP($C10,merchants!$A$2:$D$41,2,FALSE),"Merchant not found") -> Merchant_018 | E10: =IFERROR(VLOOKUP($C10, merchants!$A$2:$D$41, 4, FALSE), "Merchant not found") -> West | F10: =IFERROR(VLOOKUP($C10, merchants!$A$2:$D$41, 3, FALSE), "Merchant not found") -> grocery | G10: 46033.372 | H10: =INT(G10) -> 46033 | I10: 799 | J10: UPI | K10: captured | L10: 44 | M10: =IF(COUNTIFS($D$2:$D10, $D10, $H$2:$H10, $H10)=1, 1, 0) -> 1 | N10: =_xlfn.IFNA(HLOOKUP($J10, fee_reference!$B$1:$E$2, 2, FALSE), 0) -> 0
A11: TXN100009 | B11: 348 | C11: 35 | D11: =IFERROR(VLOOKUP($C11,merchants!$A$2:$D$41,2,FALSE),"Merchant not found") -> Merchant_035 | E11: =IFERROR(VLOOKUP($C11, merchants!$A$2:$D$41, 4, FALSE), "Merchant not found") -> East | F11: =IFERROR(VLOOKUP($C11, merchants!$A$2:$D$41, 3, FALSE), "Merchant not found") -> recharge | G11: 46043.684 | H11: =INT(G11) -> 46043 | I11: 299 | J11: UPI | K11: captured | L11: 42 | M11: =IF(COUNTIFS($D$2:$D11, $D11, $H$2:$H11, $H11)=1, 1, 0) -> 1 | N11: =_xlfn.IFNA(HLOOKUP($J11, fee_reference!$B$1:$E$2, 2, FALSE), 0) -> 0
A12: TXN100010 | B12: 134 | C12: 12 | D12: =IFERROR(VLOOKUP($C12,merchants!$A$2:$D$41,2,FALSE),"Merchant not found") -> Merchant_012 | E12: =IFERROR(VLOOKUP($C12, merchants!$A$2:$D$41, 4, FALSE), "Merchant not found") -> East | F12: =IFERROR(VLOOKUP($C12, merchants!$A$2:$D$41, 3, FALSE), "Merchant not found") -> ecommerce | G12: 46023.164 | H12: =INT(G12) -> 46023 | I12: 49 | J12: UPI | K12: captured | L12: 74 | M12: =IF(COUNTIFS($D$2:$D12, $D12, $H$2:$H12, $H12)=1, 1, 0) -> 1 | N12: =_xlfn.IFNA(HLOOKUP($J12, fee_reference!$B$1:$E$2, 2, FALSE), 0) -> 0
A13: TXN100011 | B13: 306 | C13: 28 | D13: =IFERROR(VLOOKUP($C13,merchants!$A$2:$D$41,2,FALSE),"Merchant not found") -> Merchant_028 | E13: =IFERROR(VLOOKUP($C13, merchants!$A$2:$D$41, 4, FALSE), "Merchant not found") -> South | F13: =IFERROR(VLOOKUP($C13, merchants!$A$2:$D$41, 3, FALSE), "Merchant not found") -> ecommerce | G13: 46031.046 | H13: =INT(G13) -> 46031 | I13: 2999 | J13: Card | K13: failed | L13: 44 | M13: =IF(COUNTIFS($D$2:$D13, $D13, $H$2:$H13, $H13)=1, 1, 0) -> 1 | N13: =_xlfn.IFNA(HLOOKUP($J13, fee_reference!$B$1:$E$2, 2, FALSE), 0) -> 0.025
... A548: TXN300031 | B548: 345 | C548: 12 | D548: =IFERROR(VLOOKUP($C548,merchants!$A$2:$D$41,2,FALSE),"Merchant not found") -> Merchant_012 | E548: =IFERROR(VLOOKUP($C548, merchants!$A$2:$D$41, 4, FALSE), "Merchant not found") -> East | F548: =IFERROR(VLOOKUP($C548, merchants!$A$2:$D$41, 3, FALSE), "Merchant not found") -> ecommerce | G548: 46045.377 | H548: =INT(G548) -> 46045 | I548: 399 | J548: Card | K548: captured | L548: 69 | M548: =IF(COUNTIFS($D$2:$D548, $D548, $H$2:$H548, $H548)=1, 1, 0) -> 0 | N548: =_xlfn.IFNA(HLOOKUP($J548, fee_reference!$B$1:$E$2, 2, FALSE), 0) -> 0.025

Sheet merchants
A1: merchant_id | B1: merchant_name | C1: category | D1: region
A2: 1 | B2: Merchant_001 | C2: ecommerce | D2: South
A3: 2 | B3: Merchant_002 | C3: grocery | D3: West
A4: 3 | B4: Merchant_003 | C4: grocery | D4: East
A5: 4 | B5: Merchant_004 | C5: ecommerce | D5: East
A6: 5 | B6: Merchant_005 | C6: recharge | D6: South
A7: 6 | B7: Merchant_006 | C7: food_delivery | D7: South
A8: 7 | B8: Merchant_007 | C8: food_delivery | D8: East
A9: 8 | B9: Merchant_008 | C9: food_delivery | D9: North
A10: 9 | B10: Merchant_009 | C10: ecommerce | D10: North
A11: 10 | B11: Merchant_010 | C11: grocery | D11: West
A12: 11 | B12: Merchant_011 | C12: ecommerce | D12: North
A13: 12 | B13: Merchant_012 | C13: ecommerce | D13: East
... A41: 40 | B41: Merchant_040 | C41: entertainment | D41: South

Sheet fee_reference
A1: Method | B1: UPI | C1: Wallet | D1: Card | E1: Netbanking
A2: Fee% | B2: 0 | C2: 0.015 | D2: 0.025 | E2: 0.01
